Workbook

Sheet 奥克兰
A1: 6月03日奥克兰分单 | L1: 2月2日 | M1: 奥克兰分单
A2: 路由码 route code | B2: 路由码 （隐藏） | C2: 到件货量（预估） Volume of goods | D2: 总数（预估） total | E2: 到件货量（实际） Volume of goods | F2: 总数（实际） total | G2: 供应商 supplier | H2: 司机 driver | I2: 是否确认 Are you sure | J2: 备注 notes | L2: 5月31日
A3: 101 | C3: 0 | G3: EMPIRE COURIER
A4: 102 | C4: 0 | G4: EMPIRE COURIER
A5: 103 | C5: 0 | G5: EMPIRE COURIER
A6: 104 | B6: 104 | C6: 55 | D6: =C6 -> 55 | E6: =IFERROR(VLOOKUP(B6,#REF!,2,0),0) -> 0 | F6: =E6 -> 0 | G6: EMPIRE COURIER | H6: 司机待定 | I6: 0 | J6: 外国
A7: 105 | C7: 55 | G7: EMPIRE COURIER
A8: 106 | C8: 73 | G8: EMPIRE COURIER
A9: 107 | C9: 63 | G9: EMPIRE COURIER
A10: 108 | C10: 44 | G10: EMPIRE COURIER
A11: 201 | C11: 46 | G11: Feng
A12: 201 A | C12: 59 | G12: Feng
A13: 201 S | C13: 7 | G13: Feng
A14: 202 | C14: 54 | G14: Feng
A15: 202 S | C15: 5 | G15: Feng
A16: 203 | C16: 34 | G16: Click'N Code
A17: 203 A | C17: 75 | G17: Click'N Code
A18: 203 B | C18: 45 | G18: Click'N Code
... A48: 311 | C48: 32 | G48: Fast donkey
A49: 312 | C49: 53 | G49: Fast donkey
A50: 401 A | C50: 29 | G50: Feng
A51: 401 B | C51: 40 | G51: Feng
A52: 401 C | C52: 45 | G52: Feng
A53: 401 S | C53: 18 | G53: Feng
A54: 402 | C54: 85 | G54: PANDA
A55: 403 | C55: 112 | G55: PANDA
A56: 404 | C56: 91 | G56: Feng
A57: 404 A | C57: 24 | G57: PANDA
A58: 404 B | C58: 21 | G58: Feng
A59: 404 S | C59: 13 | G59: Feng
A60: 405 | C60: 10 | G60: Click'N Code
A61: 405 A | C61: 0 | G61: Click'N Code
... A84: 507 | C84: 6 | G84: EMPIRE COURIER
A85: 508 | C85: 0 | G85: EMPIRE COURIER
A86: 601 | C86: 52 | G86: PANDA
A87: 601 A | C87: 21 | G87: Maximage
A88: 602 | C88: 57 | G88: Maximage
A89: 603 | C89: 76 | G89: Click'N Code
A90: 604 | C90: 61 | G90: Feng
A91: 604 A | C91: 44 | G91: Feng
...

Sheet 非奥克兰
A1: 6月03日非奥克兰到件货量 | I1: 2月2日 | J1: 非奥克兰到件货量 | M1: 城市名 | N1: Booth 托盘单价 | O1: ADMIN
A2: 派件网点 | B2: 派件网点(有变动） | C2: 到件货量 | D2: 3月12日数量 | E2: 占比 | F2: 外省菜鸟到货量 | H2: 135 | I2: 3L预测板数 | M2: RTR | N2: 95 | O2: 35
A3: HMT | B3: Hamilton | C3: 1556 | D3: 234 | E3: 0.081818182 | F3: 310 | H3: RTR | I3: 2.99 | M3: TRG | N3: 85 | O3: 35
A4: TRG | B4: Tauranga | C4: 1067 | D4: 127 | E4: 0.044405594 | F4: 186 | H4: HMT | I4: 11.53 | M4: NPL&HST | N4: 125 | O4: 35
A5: WLT | C5: 0 | D5: 105 | E5: 0.036713287 | F5: 0 | H5: TRG | I5: 7.9
A6: NPL | B6: Napier | C6: 435 | D6: 60 | E6: 0.020979021 | F6: 99 | H6: HST | I6: 2.27
A7: PMN | C7: 0 | D7: 54 | E7: 0.018881119 | F7: 0 | H7: NPL | I7: 3.22
A8: RTR | B8: Rotorua | C8: 403 | D8: 53 | E8: 0.018531469 | F8: 96 | H8: WGR | I8: 2.64
A9: WGR | C9: 356 | D9: 51 | E9: 0.017832168 | F9: 0 | H9: WLT | I9: 0
A10: HST | C10: 306 | D10: 34 | E10: 0.011888112 | F10: 26 | H10: 总计 | I10: 24.92
A11: 总计 | C11: 4123 | D11: =SUM(D3:D10) -> 718 | E11: 4000 | F11: 717
A13: Aliexpress 单量 | F13: 当天总量（奥克兰 + 外省） | H13: 350 | I13: 5L预测板数
A14: 3452 | F14: 9290(5167 + 4123) | H14: RTR | I14: 1.15
C15: 本地件： | H15: HMT | I15: 4.45
H16: TRG | I16: 3.05
H17: HST | I17: 0.87
H18: NPL | I18: 1.24
H19: WRG | I19: 1.02
H20: WLT | I20: 0
H21: 总计 | I21: 9.61

Sheet 奥克兰透视
A3: 路由码 | B3: 计数项:运单号 | D3: 是否存在 | K3: =奥克兰!L2 -> 5月31日 | L3: HMT各条线预测 | N3: TRG各条线预测 | O3: NPL各条线预测
A4: 104 | B4: 55 | D4: 1 | L4: RTR各条线预测 | N4: WLT各线路预测
A5: 105 | B5: 55 | D5: =IF(COUNTIF(奥克兰!A:A,A5)>0,1,0) -> 1 | N5: WRG各线路预测
A6: 106 | B6: 73 | D6: =IF(COUNTIF(奥克兰!A:A,A6)>0,1,0) -> 1 | F6: =K3&N5 -> 5月31日WRG各线路预测
A7: 107 | B7: 63 | D7: =IF(COUNTIF(奥克兰!A:A,A7)>0,1,0) -> 1 | F7: Route Code | G7: Quantity | J7: =K3&L3 -> 5月31日HMT各条线预测 | M7: =K3&N4 -> 5月31日WLT各线路预测
A8: 108 | B8: 44 | D8: =IF(COUNTIF(奥克兰!A:A,A8)>0,1,0) -> 1 | F8: WGR01 | G8: 134 | J8: Route Code | K8: Quantity | M8: Route Code | N8: Quantity
A9: 201 | B9: 46 | D9: =IF(COUNTIF(奥克兰!A:A,A9)>0,1,0) -> 1 | F9: WGR03 | G9: 222 | J9: HMT01 | K9: 17 | M9: WLT 01 | N9: 0
A10: 201 A | B10: 59 | D10: =IF(COUNTIF(奥克兰!A:A,A10)>0,1,0) -> 1 | J10: HMT1A | K10: 36 | M10: WLT 02 | N10: 0
A11: 201 S | B11: 7 | D11: =IF(COUNTIF(奥克兰!A:A,A11)>0,1,0) -> 1 | J11: HMT1C | K11: 84 | M11: WLT 03 | N11: 0
A12: 202 | B12: 54 | D12: =IF(COUNTIF(奥克兰!A:A,A12)>0,1,0) -> 1 | J12: HMT1B | K12: 127 | M12: WLT 04 | N12: 0
A13: 202 S | B13: 5 | D13: =IF(COUNTIF(奥克兰!A:A,A13)>0,1,0) -> 1 | G13: =SUM(G8:G12) -> 356 | J13: HMT2A | K13: 144 | M13: WLT 05 | N13: 0
A14: 203 | B14: 34 | D14: =IF(COUNTIF(奥克兰!A:A,A14)>0,1,0) -> 1 | J14: HMT2B | K14: 33 | M14: WLT 06 | N14: 0
A15: 203 A | B15: 75 | D15: =IF(COUNTIF(奥克兰!A:A,A15)>0,1,0) -> 1 | J15: HMT03 | K15: 159 | M15: WLT 07 | N15: 0
A16: 203 B | B16: 45 | D16: =IF(COUNTIF(奥克兰!A:A,A16)>0,1,0) -> 1 | J16: HMT04 | K16: 31 | M16: WLT 08 | N16: 0
A17: 204 | B17: 149 | D17: =IF(COUNTIF(奥克兰!A:A,A17)>0,1,0) -> 1 | J17: HMT4A | K17: 202 | M17: WLT 09 | N17: 0
A18: 204 S | B18: 2 | D18: =IF(COUNTIF(奥克兰!A:A,A18)>0,1,0) -> 1 | J18: HMT4B | K18: 89 | M18: WLT 10 | N18: 0
A19: 205 | B19: 48 | D19: =IF(COUNTIF(奥克兰!A:A,A19)>0,1,0) -> 1 | J19: HMT05 | K19: 114 | N19: =SUM(N9:N18) -> 0
A20: 206 | B20: 37 | D20: =IF(COUNTIF(奥克兰!A:A,A20)>0,1,0) -> 1 | J20: HMT06 | K20: 167
A21: 207 | B21: 43 | D21: =IF(COUNTIF(奥克兰!A:A,A21)>0,1,0) -> 1 | J21: HMT07 | K21: 35
A22: 207 S | B22: 9 | D22: =IF(COUNTIF(奥克兰!A:A,A22)>0,1,0) -> 1 | J22: HMT08 | K22: 140
A23: 208 | B23: 99 | D23: =IF(COUNTIF(奥克兰!A:A,A23)>0,1,0) -> 1 | J23: HMT09 | K23: 152
A24: 209 | B24: 33 | D24: =IF(COUNTIF(奥克兰!A:A,A24)>0,1,0) -> 1 | K24: =SUM(K9:K23) -> 1530
A25: 210 | B25: 169 | D25: =IF(COUNTIF(奥克兰!A:A,A25)>0,1,0) -> 1
A26: 211 | B26: 118 | D26: =IF(COUNTIF(奥克兰!A:A,A26)>0,1,0) -> 1
A27: 211 A | B27: 112 | D27: =IF(COUNTIF(奥克兰!A:A,A27)>0,1,0) -> 1
A28: 301 | B28: 77 | D28: =IF(COUNTIF(奥克兰!A:A,A28)>0,1,0) -> 1 | G28: =K3&L4 -> 5月31日RTR各条线预测 | J28: =K3&N3 -> 5月31日TRG各条线预测
A29: 301 S | B29: 8 | D29: =IF(COUNTIF(奥克兰!A:A,A29)>0,1,0) -> 1 | G29: Route Code | H29: Quantity | J29: TRG1 | K29: 282
A30: 302 | B30: 77 | D30: =IF(COUNTIF(奥克兰!A:A,A30)>0,1,0) -> 1 | G30: RTR1 | H30: 214 | J30: TRG2 | K30: 405
A31: 303 | B31: 41 | D31: =IF(COUNTIF(奥克兰!A:A,A31)>0,1,0) -> 1 | G31: RTR2 | H31: 189 | J31: TRG3 | K31: 380
A32: 304 | B32: 86 | D32: =IF(COUNTIF(奥克兰!A:A,A32)>0,1,0) -> 1 | H32: =SUM(H30:H31) -> 403 | J32: TRG04 | K32: 0
A33: 305 | B33: 126 | D33: =IF(COUNTIF(奥克兰!A:A,A33)>0,1,0) -> 1 | J33: TRG08 | K33: 0
A34: 306 | B34: 169 | D34: =IF(COUNTIF(奥克兰!A:A,A34)>0,1,0) -> 1 | J34: TRG10 | K34: 0
A35: 307 | B35: 16 | D35: =IF(COUNTIF(奥克兰!A:A,A35)>0,1,0) -> 1 | J35: 总计 | K35: =SUM(K29:K34) -> 1067
A36: 307 A | B36: 89 | D36: =IF(COUNTIF(奥克兰!A:A,A36)>0,1,0) -> 1
A37: 307 B | B37: 76 | D37: =IF(COUNTIF(奥克兰!A:A,A37)>0,1,0) -> 1
A38: 308 | B38: 39 | D38: =IF(COUNTIF(奥克兰!A:A,A38)>0,1,0) -> 1
A39: 308 A | B39: 18 | D39: =IF(COUNTIF(奥克兰!A:A,A39)>0,1,0) -> 1 | J39: =K3&O3 -> 5月31日NPL各条线预测
A40: 308 B | B40: 54 | D40: =IF(COUNTIF(奥克兰!A:A,A40)>0,1,0) -> 1 | J40: NPL01 | K40: 111
A41: 308 C | B41: 40 | D41: =IF(COUNTIF(奥克兰!A:A,A41)>0,1,0) -> 1 | J41: NPL01A | K41: 47
A42: 308 D | B42: 92 | D42: =IF(COUNTIF(奥克兰!A:A,A42)>0,1,0) -> 1 | J42: NPL02 | K42: 157
...

Sheet Sheet3
A1: 运单号 | B1: 参考订单号 | C1: 面单号 | D1: 任务单号 | E1: 车牌号 | F1: 集托号 | G1: 原运单号 | H1: 创建时间 | I1: 商家编号 | J1: 寄件公司 | K1: 揽收司机名称 | L1: 揽收司机账号 | M1: 实收网点 | N1: 收件时间 | O1: 预约派送日期 | P1: 收件门牌号 | Q1: 最新扫描类型 | R1: 最新扫描时间 | S1: 最新扫描网点 | T1: 最新问题件类型 | U1: 最新问题件原因 | V1: 退件状态 | W1: 退件新单号 | X1: 退件扫描时间 | Y1: 退货最新扫描时间 | Z1: 退件最新扫描操作 | AA1: 退件原因 | AB1: 派件网点 | AC1: 派件网点简码 | AD1: 派件司机 | AE1: 派件司机编号 | AF1: 派件司机所属供应商 | AG1: 派件司机所属供应商编码 | AH1: 拦截状态 | AI1: 完结状态 | AJ1: 完结时间 | AK1: 配送状态 | AL1: 上架网点 | AM1: 库位编号 | AN1: 订单类型 | AO1: 主阶段 | AP1: 子阶段 | AQ1: 当前标记 | AR1: 路由码 | AS1: 收件人姓名 | AT1: 收件省 | AU1: 收件市 | AV1: 收件区 | AW1: 邮编 | AX1: 预派件网点名称 | AY1: 预派件网点编码 | AZ1: 提货网点 | BA1: 派件时间 | BB1: 签收时间 | BC1: 收件街道 | BD1: 收件人详细地址 | BE1: 目的国首次到件时间 | BF1: 首DC到件时间 | BG1: 首RDC到件时间 | BH1: 派件站点卸车时间 | BI1: 电话 | BJ1: 寄件省 | BK1: 寄件城市 | BL1: 寄件区域 | BM1: 详细地址 | BN1: 地址经纬度 | BO1: 最新问题件时间 | BP1: NDR状态 | BQ1: NDR时间 | BR1: 代收货款 | BS1: PPD/COD | BT1: sku | BU1: 货物类别 | BV1: 件数(包裹) | BW1: 件数 | BX1: 商家上传体积(cm³) | BY1: 商家上传重量 | BZ1: 商家上传体积重量(kg) | CA1: 收件总重量 | CB1: 收件总体积 | CC1: 收件体积重量(kg) | CD1: 上传申报价值 | CE1: 系统申报价值(USD) | CF1: 允许拆包 | CG1: 大小 | CH1: 寄件国家 | CI1: 寄件联系人 | CJ1: 收件电话 | CK1: 收件邮箱 | CL1: 收件国家 | CM1: 派件次数 | CN1: SKU（备用） | CO1: 默认处理方式 | CP1: 退件收件人 | CQ1: 退件收件人电话 | CR1: 退件收件人省 | CS1: 退件收件人市 | CT1: 退件收件人区 | CU1: 退件收件人邮编 | CV1: 退件收件人地址 | CW1: 退件寄件人 | CX1: 退件寄件人电话 | CY1: 退件寄件省 | CZ1: 退件寄件市 | DA1: 退件寄件邮编 | DB1: 退件寄件地址 | DC1: 退件派件网点编号
A2: 3661049959968 | B2: LP00747389812425 | G2: 2025-07-23 00:31:18 | R2: 否 | X2: AucklandDS | Y2: AKL | AD2: 否 | AE2: 否 | AK2: 退返商家 | AL2: 配送订单 | AN2: TN Marketing Limited - Atn: Julie Comber | AO2: Auckland | AP2: Auckland | AR2: 211 | AS2: 1072 | AT2: AucklandDS | AU2: S210235001 | AZ2: 25 | BA2: 10 | BB2: 1.181 | BC2: 0.002 | BD2: 0 | BE2: 0 | BF2: 0 | BG2: 9.75 | BH2: 9.75 | BI2: 不允许 | BK2: NZL | BL2: iMile | BM2: 223539576 | BN2: juliecomber@xtra.co.nz | BO2: NZL | BP2: 0 | BQ2: 0 | CK2: 否 | CM2: Auckland
A3: 3661049960514 | B3: LP00749687034328 | G3: 2025-07-23 00:31:17 | R3: 否 | X3: AucklandDS | Y3: AKL | AD3: 否 | AE3: 否 | AK3: 销毁 | AL3: 配送订单 | AN3: Libby McLuckie | AO3: Auckland | AP3: Auckland | AR3: 406 | AS3: 0614 | AT3: AucklandDS | AU3: S210235001 | AZ3: 1 | BA3: 10 | BB3: 0.238 | BC3: 0.002 | BD3: 0 | BE3: 0 | BF3: 0 | BG3: 14.09 | BH3: 14.09 | BI3: 不允许 | BK3: NZL | BL3: iMile | BM3: 021911492 | BN3: libbymcluckie@gmail.com | BO3: NZL | BP3: 0 | BQ3: 0 | CK3: 否 | CM3: Auckland
A4: 3661049958884 | B4: LP00749265432354 | G4: 2025-07-23 00:31:17 | R4: 否 | X4: AucklandDS | Y4: AKL | AD4: 否 | AE4: 否 | AK4: 退返商家 | AL4: 配送订单 | AN4: Karl (Service & Control Ltd) | AO4: Auckland | AP4: Auckland | AR4: 202 | AS4: 1026 | AT4: AucklandDS | AU4: S210235001 | AZ4: 1 | BA4: 10 | BB4: 0.519 | BC4: 0.002 | BD4: 0 | BE4: 0 | BF4: 0 | BG4: 81.55 | BH4: 81.55 | BI4: 不允许 | BK4: NZL | BL4: iMile | BM4: 0212808586 | BN4: admin@serviceandcontrol.com | BO4: NZL | BP4: 0 | BQ4: 0 | CK4: 否 | CM4: Auckland
A5: 3661049960699 | B5: LP00747826174716 | G5: 2025-07-23 00:31:17 | R5: 否 | X5: AucklandDS | Y5: AKL | AD5: 否 | AE5: 否 | AK5: 销毁 | AL5: 配送订单 | AN5: jun Kim | AO5: Auckland | AP5: Auckland | AR5: 405 | AS5: 0612 | AT5: AucklandDS | AU5: S210235001 | AZ5: 1 | BA5: 10 | BB5: 0.282 | BC5: 0.002 | BD5: 0 | BE5: 0 | BF5: 0 | BG5: 10 | BH5: 10 | BI5: 不允许 | BK5: NZL | BL5: iMile | BM5: +6402108685565 | BN5: lalalang1979@gmail.com | BO5: NZL | BP5: 0 | BQ5: 0 | CK5: 否 | CM5: Auckland
A6: 3661049961057 | B6: LP00749848243562 | G6: 2025-07-23 00:31:37 | R6: 否 | X6: AucklandDS | Y6: AKL | AD6: 否 | AE6: 否 | AK6: 销毁 | AL6: 配送订单 | AN6: Meadow Reihana | AO6: Auckland | AP6: Auckland | AR6: 209 | AS6: 1062 | AT6: AucklandDS | AU6: S210235001 | AZ6: 2 | BA6: 10 | BB6: 0.164 | BC6: 0.002 | BD6: 0 | BE6: 0 | BF6: 0 | BG6: 13.28 | BH6: 13.28 | BI6: 不允许 | BK6: NZL | BL6: iMile | BM6: 0211885286 | BN6: meadowreihana12@gmail.com | BO6: NZL | BP6: 0 | BQ6: 0 | CK6: 否 | CM6: Auckland
A7: 3661049961297 | B7: LP00749496240649 | G7: 2025-07-23 00:31:17 | R7: 否 | X7: AucklandDS | Y7: AKL | AD7: 否 | AE7: 否 | AK7: 销毁 | AL7: 配送订单 | AN7: Gurpreet Singh | AO7: Auckland | AP7: Auckland | AR7: 108 | AS7: 1024 | AT7: AucklandDS | AU7: S210235001 | AZ7: 3 | BA7: 10 | BB7: 0.926 | BC7: 0.002 | BD7: 0 | BE7: 0 | BF7: 0 | BG7: 26.41 | BH7: 26.41 | BI7: 不允许 | BK7: NZL | BL7: iMile | BM7: +6402040905850 | BN7: gpsingh1723@gmail.com | BO7: NZL | BP7: 0 | BQ7: 0 | CK7: 否 | CM7: Auckland
A8: 3661049959872 | B8: LP00747459101654 | G8: 2025-07-23 00:31:17 | R8: 否 | X8: AucklandDS | Y8: AKL | AD8: 否 | AE8: 否 | AK8: 销毁 | AL8: 配送订单 | AN8: Ronan Murphy | AO8: Auckland | AP8: Auckland | AR8: 208 | AS8: 1061 | AT8: AucklandDS | AU8: S210235001 | AZ8: 1 | BA8: 10 | BB8: 0.592 | BC8: 0.002 | BD8: 0 | BE8: 0 | BF8: 0 | BG8: 4.48 | BH8: 4.48 | BI8: 不允许 | BK8: NZL | BL8: iMile | BM8: 21881975 | BN8: master.ronan@hotmail.com | BO8: NZL | BP8: 0 | BQ8: 0 | CK8: 否 | CM8: Auckland
A9: 3661049961212 | B9: LP00748933670324 | G9: 2025-07-23 00:31:17 | R9: 否 | X9: AucklandDS | Y9: AKL | AD9: 否 | AE9: 否 | AK9: 销毁 | AL9: 配送订单 | AN9: Shaun Drummond | AO9: Auckland | AP9: Auckland | AR9: 309 | AS9: 0930 | AT9: AucklandDS | AU9: S210235001 | AZ9: 2 | BA9: 10 | BB9: 0.28 | BC9: 0.002 | BD9: 0 | BE9: 0 | BF9: 0 | BG9: 27.65 | BH9: 27.65 | BI9: 不允许 | BK9: NZL | BL9: iMile | BM9: 21426383 | BN9: shaun@sptconsulting.co.nz | BO9: NZL | BP9: 0 | BQ9: 0 | CK9: 否 | CM9: Auckland
A10: 3661049961324 | B10: LP00749007531773 | G10: 2025-07-23 00:31:26 | R10: 否 | X10: AucklandDS | Y10: AKL | AD10: 否 | AE10: 否 | AK10: 销毁 | AL10: 配送订单 | AN10: Ivan Z T Feng | AO10: Auckland | AP10: Auckland | AR10: 107 | AS10: 1023 | AT10: AucklandDS | AU10: S210235001 | AZ10: 2 | BA10: 10 | BB10: 1.015 | BC10: 0.002 | BD10: 0 | BE10: 0 | BF10: 0 | BG10: 54.25 | BH10: 54.25 | BI10: 不允许 | BK10: NZL | BL10: iMile | BM10: 274765934 | BN10: ztfeng@gmail.com | BO10: NZL | BP10: 0 | BQ10: 0 | CK10: 否 | CM10: Auckland
A11: 3661049959521 | B11: AP00749651196273 | G11: 2025-07-23 00:31:17 | R11: 否 | X11: AucklandDS | Y11: AKL | AD11: 否 | AE11: 否 | AK11: 退返商家 | AL11: 配送订单 | AN11: Jonathan Busato | AO11: Auckland | AP11: Auckland | AR11: 203 | AS11: 1042 | AT11: AucklandDS | AU11: S210235001 | AZ11: 1 | BA11: 10 | BB11: 0.069 | BC11: 0.002 | BD11: 0 | BE11: 0 | BF11: 0 | BG11: 6.78 | BH11: 6.78 | BI11: 不允许 | BK11: NZL | BL11: iMile | BM11: +6402108269803 | BN11: jbusato402@hotmail.co.uk | BO11: NZL | BP11: 0 | BQ11: 0 | CK11: 否 | CM11: Auckland
A12: 3661049988792 | B12: LP00748712565401 | G12: 2025-07-23 00:31:17 | R12: 否 | X12: AucklandDS | Y12: AKL | AD12: 否 | AE12: 否 | AK12: 退返商家 | AL12: 配送订单 | AN12: Christopher peck | AO12: Auckland | AP12: Auckland | AR12: 404 | AS12: 0610 | AT12: AucklandDS | AU12: S210235001 | AZ12: 2 | BA12: 10 | BB12: 0.493 | BC12: 0.002 | BD12: 0 | BE12: 0 | BF12: 0 | BG12: 18.92 | BH12: 18.92 | BI12: 不允许 | BK12: NZL | BL12: iMile | BM12: 021968057 | BN12: cjp9784@hotmail.com | BO12: NZL | BP12: 0 | BQ12: 0 | CK12: 否 | CM12: Auckland
A13: 3661049961513 | B13: LP00747929159387 | G13: 2025-07-23 00:31:17 | R13: 否 | X13: AucklandDS | Y13: AKL | AD13: 否 | AE13: 否 | AK13: 销毁 | AL13: 配送订单 | AN13: Beth Healy | AO13: Auckland | AP13: Auckland | AR13: 309 | AS13: 0932 | AT13: AucklandDS | AU13: S210235001 | AZ13: 4 | BA13: 10 | BB13: 0.395 | BC13: 0.002 | BD13: 0 | BE13: 0 | BF13: 0 | BG13: 23.42 | BH13: 23.42 | BI13: 不允许 | BK13: NZL | BL13: iMile | BM13: +6464212332695 | BN13: beth_pike@hotmail.com | BO13: NZL | BP13: 0 | BQ13: 0 | CK13: 否 | CM13: Auckland
... A86: 3661049960277 | B86: LP00748888713368 | G86: 2025-07-23 00:31:18 | R86: 否 | X86: AucklandDS | Y86: AKL | AD86: 否 | AE86: 否 | AK86: 销毁 | AL86: 配送订单 | AN86: Danie Brink | AO86: Auckland | AP86: Auckland | AR86: 606 | AS86: 2018 | AT86: AucklandDS | AU86: S210235001 | AZ86: 7 | BA86: 10 | BB86: 0.693 | BC86: 0.002 | BD86: 0 | BE86: 0 | BF86: 0 | BG86: 5.72 | BH86: 5.72 | BI86: 不允许 | BK86: NZL | BL86: iMile | BM86: 212703396 | BN86: 1danie.brink@gmail.com | BO86: NZL | BP86: 0 | BQ86: 0 | CK86: 否 | CM86: Auckland
A87: 3661049960752 | B87: LP00749539351045 | G87: 2025-07-23 00:31:18 | R87: 否 | X87: AucklandDS | Y87: AKL | AD87: 否 | AE87: 否 | AK87: 退返商家 | AL87: 配送订单 | AN87: Reseda | AO87: Auckland | AP87: Auckland | AQ87: Auckland | AR87: 405 | AS87: 0612 | AT87: AucklandDS | AU87: S210235001 | AZ87: 5 | BA87: 10 | BB87: 0.846 | BC87: 0.002 | BD87: 0 | BE87: 0 | BF87: 0 | BG87: 33.57 | BH87: 33.57 | BI87: 不允许 | BK87: NZL | BL87: iMile | BM87: 211594449 | BN87: sakuraina@qq.com | BO87: NZL | BP87: 0 | BQ87: 0 | CK87: 否 | CM87: Auckland
A88: 3661049958687 | B88: LP00748118294742 | G88: 2025-07-23 00:31:17 | R88: 否 | X88: AucklandDS | Y88: AKL | AD88: 否 | AE88: 否 | AK88: 退返商家 | AL88: 配送订单 | AN88: Anthoney Bell | AO88: Auckland | AP88: Papakura | AR88: 503 A | AS88: 2110 | AT88: AucklandDS | AU88: S210235001 | AZ88: 40 | BA88: 10 | BB88: 2.582 | BC88: 0.002 | BD88: 0 | BE88: 0 | BF88: 0 | BG88: 80 | BH88: 80 | BI88: 不允许 | BK88: NZL | BL88: iMile | BM88: 0225394910 | BN88: jodi@trenchmate.co.nz | BO88: NZL | BP88: 0 | BQ88: 0 | CK88: 否 | CM88: Auckland
A89: 3661049988687 | B89: LP00746988515010 | G89: 2025-07-23 00:31:17 | R89: 否 | X89: AucklandDS | Y89: AKL | AD89: 否 | AE89: 否 | AK89: 销毁 | AL89: 配送订单 | AN89: Richard Moyle | AO89: Auckland | AP89: Auckland | AR89: 603 | AS89: 2013 | AT89: AucklandDS | AU89: S210235001 | AZ89: 2 | BA89: 10 | BB89: 0.595 | BC89: 0.002 | BD89: 0 | BE89: 0 | BF89: 0 | BG89: 3.6 | BH89: 3.6 | BI89: 不允许 | BK89: NZL | BL89: iMile | BM89: 275587547 | BN89: rmoyle1980@gmail.com | BO89: NZL | BP89: 0 | BQ89: 0 | CK89: 否 | CM89: Auckland
A90: 3661049960658 | B90: LP00749936712332 | G90: 2025-07-23 00:31:17 | R90: 否 | X90: AucklandDS | Y90: AKL | AD90: 否 | AE90: 否 | AK90: 销毁 | AL90: 配送订单 | AN90: Kuang sheng | AO90: Auckland | AP90: Auckland | AR90: 309 A | AS90: 0792 | AT90: AucklandDS | AU90: S210235001 | AZ90: 1 | BA90: 10 | BB90: 0.423 | BC90: 0.002 | BD90: 0 | BE90: 0 | BF90: 0 | BG90: 6.29 | BH90: 6.29 | BI90: 不允许 | BK90: NZL | BL90: iMile | BM90: 0211039722 | BN90: kuang@sksstudio.co.nz | BO90: NZL | BP90: 0 | BQ90: 0 | CK90: 否 | CM90: Auckland
A91: 3661049958211 | B91: LP00749398789931 | G91: 2025-07-23 00:31:17 | R91: 否 | X91: AucklandDS | Y91: AKL | AD91: 否 | AE91: 否 | AK91: 销毁 | AL91: 配送订单 | AN91: satish goundar | AO91: Auckland | AP91: Auckland | AR91: 502 | AS91: 2103 | AT91: AucklandDS | AU91: S210235001 | AZ91: 1 | BA91: 10 | BB91: 0.091 | BC91: 0.002 | BD91: 0 | BE91: 0 | BF91: 0 | BG91: 3 | BH91: 3 | BI91: 不允许 | BK91: NZL | BL91: iMile | BM91: 0272032468 | BN91: google_108605002110424007533@aliexpress.com | BO91: NZL | BP91: 0 | BQ91: 0 | CK91: 否 | CM91: Auckland
A92: 3661049988558 | B92: LP00748796210309 | G92: 2025-07-23 00:31:17 | R92: 否 | X92: AucklandDS | Y92: AKL | AD92: 否 | AE92: 否 | AK92: 销毁 | AL92: 配送订单 | AN92: Julius Hart | AO92: Auckland | AP92: Auckland | AR92: 309 | AS92: 0931 | AT92: AucklandDS | AU92: S210235001 | AZ92: 2 | BA92: 10 | BB92: 0.681 | BC92: 0.002 | BD92: 0 | BE92: 0 | BF92: 0 | BG92: 23.38 | BH92: 23.38 | BI92: 不允许 | BK92: NZL | BL92: iMile | BM92: 021642901 | BN92: hartorewa@gmail.com | BO92: NZL | BP92: 0 | BQ92: 0 | CK92: 否 | CM92: Auckland
A93: 3661049960650 | B93: LP00748604648918 | G93: 2025-07-23 00:31:18 | R93: 否 | X93: Hamilton | Y93: HMT | AD93: 否 | AE93: 否 | AK93: 销毁 | AL93: 配送订单 | AN93: Stefanie Reid | AO93: Hamilton | AP93: Hamilton | AR93: HMT04 | AS93: 3210 | AT93: Hamilton | AU93: S210259801 | AZ93: 2 | BA93: 10 | BB93: 0.078 | BC93: 0.002 | BD93: 0 | BE93: 0 | BF93: 0 | BG93: 4.06 | BH93: 4.06 | BI93: 不允许 | BK93: NZL | BL93: iMile | BM93: 0224733794 | BN93: hekate@hotmail.co.nz | BO93: NZL | BP93: 0 | BQ93: 0 | CK93: 否 | CM93: Auckland
A94: 3661049961237 | B94: LP00749593476335 | G94: 2025-07-23 00:31:18 | R94: 否 | X94: AucklandDS | Y94: AKL | AD94: 否 | AE94: 否 | AK94: 退返商家 | AL94: 配送订单 | AN94: Ross George | AO94: Auckland | AP94: Auckland | AR94: 106 | AS94: 1022 | AT94: AucklandDS | AU94: S210235001 | AZ94: 29 | BA94: 10 | BB94: 0.378 | BC94: 0.002 | BD94: 0 | BE94: 0 | BF94: 0 | BG94: 36.86 | BH94: 36.86 | BI94: 不允许 | BK94: NZL | BL94: iMile | BM94: 21662900 | BN94: casuallydressedguy@gmail.com | BO94: NZL | BP94: 0 | BQ94: 0 | CK94: 否 | CM94: Auckland
A95: 3661049959726 | B95: LP00748391054245 | G95: 2025-07-23 00:31:28 | R95: 否 | X95: AucklandDS | Y95: AKL | AD95: 否 | AE95: 否 | AK95: 退返商家 | AL95: 配送订单 | AN95: Barbara Egorova | AO95: Auckland | AP95: Auckland | AR95: 307 | AS95: 0630 | AT95: AucklandDS | AU95: S210235001 | AZ95: 3 | BA95: 10 | BB95: 0.17 | BC95: 0.002 | BD95: 0 | BE95: 0 | BF95: 0 | BG95: 19.93 | BH95: 19.93 | BI95: 不允许 | BK95: NZL | BL95: iMile | BM95: 222906275 | BN95: evarvara051@gmail.com | BO95: NZL | BP95: 0 | BQ95: 0 | CK95: 否 | CM95: Auckland
A96: 3661049958752 | B96: LP00749407165172 | G96: 2025-07-23 00:31:18 | R96: 否 | X96: Hamilton | Y96: HMT | AD96: 否 | AE96: 否 | AK96: 退返商家 | AL96: 配送订单 | AN96: Brent Seeney | AO96: Hamilton | AP96: Hamilton | AR96: HMT06 | AS96: 3216 | AT96: Hamilton | AU96: S210259801 | AZ96: 1 | BA96: 10 | BB96: 0.147 | BC96: 0.002 | BD96: 0 | BE96: 0 | BF96: 0 | BG96: 6 | BH96: 6 | BI96: 不允许 | BK96: NZL | BL96: iMile | BM96: 274522226 | BN96: brent.seeney@gmail.com | BO96: NZL | BP96: 0 | BQ96: 0 | CK96: 否 | CM96: Auckland
A97: 3661049960957 | B97: LP00749500026089 | G97: 2025-07-23 00:31:18 | R97: 否 | X97: AucklandDS | Y97: AKL | AD97: 否 | AE97: 否 | AK97: 销毁 | AL97: 配送订单 | AN97: Martin Weekes | AO97: Auckland | AP97: Auckland | AR97: 303 | AS97: 0624 | AT97: AucklandDS | AU97: S210235001 | AZ97: 2 | BA97: 10 | BB97: 0.036 | BC97: 0.002 | BD97: 0 | BE97: 0 | BF97: 0 | BG97: 2 | BH97: 2 | BI97: 不允许 | BK97: NZL | BL97: iMile | BM97: 21738622 | BN97: mackyave@gmail.com | BO97: NZL | BP97: 0 | BQ97: 0 | CK97: 否 | CM97: Auckland
A98: 3661049959485 | B98: LP00747834681386 | G98: 2025-07-23 00:31:17 | R98: 否 | X98: Tauranga | Y98: TRG | AD98: 否 | AE98: 否 | AK98: 退返商家 | AL98: 配送订单 | AN98: Simon Aiken | AO98: Bay of Plenty | AP98: Tauranga | AR98: TRG1 | AS98: 3110 | AT98: Tauranga | AU98: S210259701 | AZ98: 3 | BA98: 10 | BB98: 0.647 | BC98: 0.002 | BD98: 0 | BE98: 0 | BF98: 0 | BG98: 16 | BH98: 16 | BI98: 不允许 | BK98: NZL | BL98: iMile | BM98: 21835363 | BN98: simon.aiken@gmail.com | BO98: NZL | BP98: 0 | BQ98: 0 | CK98: 否 | CM98: Auckland
A99: 3661049959984 | B99: LP00749538739296 | G99: 2025-07-23 00:31:18 | R99: 否 | X99: Hamilton | Y99: HMT | AD99: 否 | AE99: 否 | AK99: 销毁 | AL99: 配送订单 | AN99: Chathura Mudalige | AO99: Hamilton | AP99: Hamilton | AR99: HMT03 | AS99: 3206 | AT99: Hamilton | AU99: S210259801 | AZ99: 3 | BA99: 10 | BB99: 1.73 | BC99: 0.002 | BD99: 0 | BE99: 0 | BF99: 0 | BG99: 30.87 | BH99: 30.87 | BI99: 不允许 | BK99: NZL | BL99: iMile | BM99: 0220712195 | BN99: chatchathura@yahoo.com | BO99: NZL | BP99: 0 | BQ99: 0 | CK99: 否 | CM99: Auckland
... A763: 3661049958449 | B763: LP00746935847831 | G763: 2025-07-23 13:40:39 | R763: 否 | X763: AucklandDS | Y763: AKL | AD763: 否 | AE763: 否 | AK763: 销毁 | AL763: 配送订单 | AN763: tintin | AO763: Auckland | AP763: Auckland | AR763: 306 | AS763: 0629 | AT763: AucklandDS | AU763: S210235001 | AZ763: 4 | BA763: 10 | BB763: 0.458 | BC763: 0.002 | BD763: 0 | BE763: 0 | BF763: 0 | BG763: 31.92 | BH763: 31.92 | BI763: 不允许 | BK763: NZL | BL763: iMile | BM763: +6402041807233 | BN763: tintinlee175@gmail.com | BO763: NZL | BP763: 0 | BQ763: 0 | CK763: 否 | CM763: Auckland
A764: 3661049960850 | B764: LP00748804298111 | G764: 2025-07-23 13:40:40 | R764: 否 | X764: Hamilton | Y764: HMT | AD764: 否 | AE764: 否 | AK764: 销毁 | AL764: 配送订单 | AN764: Marsha Matthews | AO764: Hamilton | AP764: Hamilton | AR764: HMT01 | AS764: 3200 | AT764: Hamilton | AU764: S210259801 | AZ764: 1 | BA764: 10 | BB764: 1.435 | BC764: 0.002 | BD764: 0 | BE764: 0 | BF764: 0 | BG764: 16 | BH764: 16 | BI764: 不允许 | BK764: NZL | BL764: iMile | BM764: 223430246 | BO764: NZL | BP764: 0 | BQ764: 0 | CK764: 否 | CM764: Auckland
A765: 3661049960560 | B765: LP00747369485668 | G765: 2025-07-23 13:40:39 | R765: 否 | X765: AucklandDS | Y765: AKL | AD765: 否 | AE765: 否 | AK765: 销毁 | AL765: 配送订单 | AN765: Debbie Grogan | AO765: Auckland | AP765: Auckland | AR765: 309 A | AS765: 0792 | AT765: AucklandDS | AU765: S210235001 | AZ765: 2 | BA765: 10 | BB765: 0.375 | BC765: 0.002 | BD765: 0 | BE765: 0 | BF765: 0 | BG765: 35.97 | BH765: 35.97 | BI765: 不允许 | BK765: NZL | BL765: iMile | BM765: +6464211552921 | BN765: surronshop.world@gmail.com | BO765: NZL | BP765: 0 | BQ765: 0 | CK765: 否 | CM765: Auckland
A766: 3661049958846 | B766: LP00748456010223 | G766: 2025-07-23 13:40:39 | R766: 否 | X766: Hamilton | Y766: HMT | AD766: 否 | AE766: 否 | AK766: 销毁 | AL766: 配送订单 | AN766: Kaity E Lunora | AO766: Hamilton | AP766: Hamilton | AR766: HMT01 | AS766: 3200 | AT766: Hamilton | AU766: S210259801 | AZ766: 5 | BA766: 10 | BB766: 0.224 | BC766: 0.002 | BD766: 0 | BE766: 0 | BF766: 0 | BG766: 19.63 | BH766: 19.63 | BI766: 不允许 | BK766: NZL | BL766: iMile | BM766: 2040076958 | BN766: leetlevamp@gmail.com | BO766: NZL | BP766: 0 | BQ766: 0 | CK766: 否 | CM766: Auckland
A767: 3661049957673 | B767: LP00749467218338 | G767: 2025-07-23 13:40:38 | R767: 否 | X767: AucklandDS | Y767: AKL | AD767: 否 | AE767: 否 | AK767: 销毁 | AL767: 配送订单 | AN767: Thomas Goodin | AO767: Auckland | AP767: Auckland | AR767: 302 | AS767: 0622 | AT767: AucklandDS | AU767: S210235001 | AZ767: 4 | BA767: 10 | BB767: 0.455 | BC767: 0.002 | BD767: 0 | BE767: 0 | BF767: 0 | BG767: 21.43 | BH767: 21.43 | BI767: 不允许 | BK767: NZL | BL767: iMile | BM767: 212080233 | BN767: thomasgoodin27@gmail.com | BO767: NZL | BP767: 0 | BQ767: 0 | CK767: 否 | CM767: Auckland
A768: 3661049959160 | B768: LP00748503110517 | G768: 2025-07-23 13:40:39 | R768: 否 | X768: AucklandDS | Y768: AKL | AD768: 否 | AE768: 否 | AK768: 销毁 | AL768: 配送订单 | AN768: Phillip Cao | AO768: Auckland | AP768: Auckland | AR768: 603 | AS768: 2013 | AT768: AucklandDS | AU768: S210235001 | AZ768: 4 | BA768: 10 | BB768: 0.943 | BC768: 0.002 | BD768: 0 | BE768: 0 | BF768: 0 | BG768: 44.62 | BH768: 44.62 | BI768: 不允许 | BK768: NZL | BL768: iMile | BM768: 224744554 | BN768: ftechz@gmail.com | BO768: NZL | BP768: 0 | BQ768: 0 | CK768: 否 | CM768: Auckland
A769: 3661049953165 | B769: LP00746716312920 | G769: 2025-07-23 13:40:38 | R769: 否 | X769: AucklandDS | Y769: AKL | AD769: 否 | AE769: 否 | AK769: 退返商家 | AL769: 配送订单 | AN769: Pareesha Kanji | AO769: Auckland | AP769: Auckland | AR769: 406 | AS769: 0614 | AT769: AucklandDS | AU769: S210235001 | AZ769: 1 | BA769: 10 | BB769: 0.346 | BC769: 0.002 | BD769: 0 | BE769: 0 | BF769: 0 | BG769: 15 | BH769: 15 | BI769: 不允许 | BK769: NZL | BL769: iMile | BM769: 2108444555 | BN769: pareeshakanji@gmail.com | BO769: NZL | BP769: 0 | BQ769: 0 | CK769: 否 | CM769: Auckland
A770: 3661049956934 | B770: LP00747533939755 | G770: 2025-07-23 13:40:39 | R770: 否 | X770: Hamilton | Y770: HMT | AD770: 否 | AE770: 否 | AK770: 销毁 | AL770: 配送订单 | AN770: Russell Osborne | AO770: Hamilton | AP770: Hamilton | AR770: HMT01 | AS770: 3200 | AT770: Hamilton | AU770: S210259801 | AZ770: 2 | BA770: 10 | BB770: 0.05 | BC770: 0.002 | BD770: 0 | BE770: 0 | BF770: 0 | BG770: 15.26 | BH770: 15.26 | BI770: 不允许 | BK770: NZL | BL770: iMile | BM770: 210564551 | BN770: r_k.osborne@clear.net.nz | BO770: NZL | BP770: 0 | BQ770: 0 | CK770: 否 | CM770: Auckland
A771: 3661049956571 | B771: LP00749338195218 | G771: 2025-07-23 13:40:38 | R771: 否 | X771: AucklandDS | Y771: AKL | AD771: 否 | AE771: 否 | AK771: 销毁 | AL771: 配送订单 | AN771: Jeff Bilkey | AO771: Auckland | AP771: Auckland | AR771: 210 | AS771: 1071 | AT771: AucklandDS | AU771: S210235001 | AZ771: 2 | BA771: 10 | BB771: 0.147 | BC771: 0.002 | BD771: 0 | BE771: 0 | BF771: 0 | BG771: 5 | BH771: 5 | BI771: 不允许 | BK771: NZL | BL771: iMile | BM771: 21918975 | BN771: jeff.bilkey@cadmethods.com | BO771: NZL | BP771: 0 | BQ771: 0 | CK771: 否 | CM771: Auckland
A772: 3661049988643 | B772: LP00749419986100 | G772: 2025-07-23 13:40:38 | R772: 否 | X772: AucklandDS | Y772: AKL | AD772: 否 | AE772: 否 | AK772: 退返商家 | AL772: 配送订单 | AN772: Christian Bartoelke | AO772: Auckland | AP772: Auckland | AR772: 304 | AS772: 0626 | AT772: AucklandDS | AU772: S210235001 | AZ772: 10 | BA772: 10 | BB772: 0.331 | BC772: 0.002 | BD772: 0 | BE772: 0 | BF772: 0 | BG772: 35.38 | BH772: 35.38 | BI772: 不允许 | BK772: NZL | BL772: iMile | BM772: 0272210558 | BN772: cbartoelke@gmail.com | BO772: NZL | BP772: 0 | BQ772: 0 | CK772: 否 | CM772: Auckland
A773: 3661049956427 | B773: LP00749211672589 | G773: 2025-07-23 13:40:39 | R773: 否 | X773: AucklandDS | Y773: AKL | AD773: 否 | AE773: 否 | AK773: 退返商家 | AL773: 配送订单 | AN773: John Chen | AO773: Auckland | AP773: Auckland | AR773: 203 | AS773: 1041 | AT773: AucklandDS | AU773: S210235001 | AZ773: 1 | BA773: 10 | BB773: 0.05 | BC773: 0.002 | BD773: 0 | BE773: 0 | BF773: 0 | BG773: 2 | BH773: 2 | BI773: 不允许 | BK773: NZL | BL773: iMile | BM773: 221038531 | BN773: johnchennz@gmail.com | BO773: NZL | BP773: 0 | BQ773: 0 | CK773: 否 | CM773: Auckland
A774: 3661049958203 | B774: LP00748502684622 | G774: 2025-07-23 13:40:40 | R774: 否 | X774: AucklandDS | Y774: AKL | AD774: 否 | AE774: 否 | AK774: 销毁 | AL774: 配送订单 | AN774: Daniel Andrews | AO774: Auckland | AP774: Auckland | AR774: 308 | AS774: 0632 | AT774: AucklandDS | AU774: S210235001 | AZ774: 3 | BA774: 10 | BB774: 0.173 | BC774: 0.002 | BD774: 0 | BE774: 0 | BF774: 0 | BG774: 20.97 | BH774: 20.97 | BI774: 不允许 | BK774: NZL | BL774: iMile | BM774: 0221531249 | BN774: salapu416@gmail.com | BO774: NZL | BP774: 0 | BQ774: 0 | CK774: 否 | CM774: Auckland
A775: 3661049958451 | B775: LP00747459064849 | G775: 2025-07-23 13:40:38 | R775: 否 | X775: Hamilton | Y775: HMT | AD775: 否 | AE775: 否 | AK775: 销毁 | AL775: 配送订单 | AN775: Carmela DelosSantos | AO775: Hamilton | AP775: Hamilton | AR775: HMT05 | AS775: 3214 | AT775: Hamilton | AU775: S210259801 | AZ775: 2 | BA775: 10 | BB775: 0.339 | BC775: 0.002 | BD775: 0 | BE775: 0 | BF775: 0 | BG775: 5.22 | BH775: 5.22 | BI775: 不允许 | BK775: NZL | BL775: iMile | BM775: 2102236108 | BN775: carmeladelossantos1999@gmail.com | BO775: NZL | BP775: 0 | BQ775: 0 | CK775: 否 | CM775: Auckland
...

Sheet 非奥克兰透视
A3: 派件网点简码 | B3: 计数项:运单号
A4: AKL | B4: 5167
A5: HMT | B5: 1556
A6: HST | B6: 306
A7: NPL | B7: 435
A8: RTR | B8: 403
A9: TRG | B9: 1067
A10: WGR | B10: 356
A11: 总计 | B11: 9290

Sheet Sheet2
A1: 运单号 | B1: 路由编码. | C1: 邮政编码 | D1: 城市 | E1: 订单类型 | F1: 入站时间 | G1: 入站滞留天数 | H1: 库位编码 | I1: 商家名称 | J1: 商家编码 | K1: 主阶段 | L1: 子阶段 | M1: 库存网点
A2: 6062025966648 | B2: 307 A | C2: 0630 | D2: Browns Bay | E2: 配送订单 | F2: 2025-06-24 11:49:17 | G2: 0 | I2: TEMU-SIN_LMD_NZL | J2: C2103951401 | K2: 派送 | L2: 新到件 | M2: AucklandDS
A3: 6061925946783 | B3: 307 A | C3: 0630 | D3: Browns Bay | E3: 配送订单 | F3: 2025-06-24 11:49:57 | G3: 0 | I3: TEMU-SIN_LMD_NZL | J3: C2103951401 | K3: 派送 | L3: 新到件 | M3: AucklandDS
A4: 6061925961682 | B4: 307 A | C4: 0630 | D4: Torbay | E4: 配送订单 | F4: 2025-06-24 11:50:30 | G4: 0 | I4: TEMU-SIN_LMD_NZL | J4: C2103951401 | K4: 派送 | L4: 新到件 | M4: AucklandDS
A5: 6061925916877 | B5: 307 A | C5: 0630 | D5: Torbay | E5: 配送订单 | F5: 2025-06-24 11:51:14 | G5: 0 | I5: TEMU-SIN_LMD_NZL | J5: C2103951401 | K5: 派送 | L5: 新到件 | M5: AucklandDS
A6: 6061925900850 | B6: 307 A | C6: 0630 | D6: Browns Bay | E6: 配送订单 | F6: 2025-06-24 11:51:17 | G6: 0 | I6: TEMU-SIN_LMD_NZL | J6: C2103951401 | K6: 派送 | L6: 新到件 | M6: AucklandDS
A7: 6061925964231 | B7: 307 A | C7: 0630 | D7: Browns Bay | E7: 配送订单 | F7: 2025-06-24 11:51:34 | G7: 0 | I7: TEMU-SIN_LMD_NZL | J7: C2103951401 | K7: 派送 | L7: 新到件 | M7: AucklandDS
A8: 6061925910708 | B8: 307 A | C8: 0630 | D8: Oteha | E8: 配送订单 | F8: 2025-06-24 11:52:15 | G8: 0 | I8: TEMU-SIN_LMD_NZL | J8: C2103951401 | K8: 派送 | L8: 新到件 | M8: AucklandDS
A9: 6061925936393 | B9: 307 A | C9: 0630 | D9: Torbay | E9: 配送订单 | F9: 2025-06-24 12:04:04 | G9: 0 | I9: TEMU-SIN_LMD_NZL | J9: C2103951401 | K9: 派送 | L9: 新到件 | M9: AucklandDS
A10: 6062025963892 | B10: 307 A | C10: 0630 | D10: Browns Bay | E10: 配送订单 | F10: 2025-06-24 12:05:03 | G10: 0 | I10: TEMU-SIN_LMD_NZL | J10: C2103951401 | K10: 派送 | L10: 新到件 | M10: AucklandDS
A11: 6061925901822 | B11: 307 A | C11: 0630 | D11: Torbay | E11: 配送订单 | F11: 2025-06-24 12:06:23 | G11: 0 | I11: TEMU-SIN_LMD_NZL | J11: C2103951401 | K11: 派送 | L11: 新到件 | M11: AucklandDS
A12: 6061925955634 | B12: 307 A | C12: 0630 | D12: Torbay | E12: 配送订单 | F12: 2025-06-24 12:07:35 | G12: 0 | I12: TEMU-SIN_LMD_NZL | J12: C2103951401 | K12: 派送 | L12: 新到件 | M12: AucklandDS
A13: 6061925939785 | B13: 307 A | C13: 0630 | D13: Browns Bay | E13: 配送订单 | F13: 2025-06-24 12:08:47 | G13: 0 | I13: TEMU-SIN_LMD_NZL | J13: C2103951401 | K13: 派送 | L13: 新到件 | M13: AucklandDS
... A110: 6061925952529 | B110: 307 A | C110: 0630 | D110: Long Bay | E110: 配送订单 | F110: 2025-06-24 13:56:53 | G110: 0 | I110: TEMU-SIN_LMD_NZL | J110: C2103951401 | K110: 派送 | L110: 新到件 | M110: AucklandDS

Sheet Sheet1
A3: 路由码 | B3: 收件城市 | C3: 计数项:运单号码
A4: 503 | C4: 22
B5: Auckland | C5: 22
A6: 503 A | C6: 226
B7: Auckland | C7: 8
B8: Karaka | C8: 25
B9: Papakura | C9: 193
A10: 503 B | C10: 154
B11: Conifer Grove | C11: 13
B12: Drury | C12: 3
B13: Opaheke | C13: 14
B14: Pahurehure | C14: 16
B15: Red Hill | C15: 9
B16: Rosehill | C16: 19
B17: Takanini | C17: 80
A18: 总计 | C18: 402

Sheet 数据源1-预测
A1: 运单号 | B1: 路由码 | C1: 派件网点简码 | D1: 派件司机 | E1: 派件司机所属供应商 | F1: 配送状态 | G1: 邮编 | H1: 派件时间 | I1: 签收时间 | J1: 系统申报价值(USD) | K1: 收件人详细地址 | L1: 地址经纬度 | M1: 参考订单号 | N1: 收件市
A2: 3661050434882 | B2: 210 | C2: AKL
A3: 3661050436611 | B3: 105 | C3: AKL
A4: 3661050436772 | B4: HMT05 | C4: HMT
A5: 3661050436914 | B5: 210 | C5: AKL
A6: 3661050437015 | B6: 601 | C6: AKL
A7: 3661050438308 | B7: HST | C7: HST
A8: 3661050438377 | B8: NPL01 | C8: NPL
A9: 3661050438528 | B9: 405 C | C9: AKL
A10: 3661050438734 | B10: 405 D | C10: AKL
A11: 3661050438837 | B11: 201 | C11: AKL
A12: 3661050438862 | B12: 404 A | C12: AKL
A13: 3661050439105 | B13: 310 | C13: AKL
... A9291: 6052826999885 | B9291: WGR01 | C9291: WGR

Sheet 数据源2-route code
A1: 运单号 | B1: 路由编码. | C1: 邮政编码 | D1: 城市 | E1: 订单类型 | F1: 入站时间 | G1: 入站滞留天数 | H1: 库位编码 | I1: 商家名称 | J1: 商家编码 | K1: 主阶段 | L1: 子阶段 | M1: 库存网点
A2: 6052725968593 | B2: 502 C | C2: 2104 | D2: Papatoetoe | E2: 配送订单 | F2: 2025-06-01 15:21:23 | G2: 23 | I2: TEMU-SIN_LMD_NZL | J2: C2103951401 | K2: 派送 | L2: 新到件 | M2: AucklandDS
A3: 6060925904506 | B3: 501 A | C3: 2022 | D3: Mangere | E3: 配送订单 | F3: 2025-06-12 13:41:58 | G3: 12 | I3: TEMU-SIN_LMD_NZL | J3: C2103951401 | K3: 派送 | L3: 新到件 | M3: AucklandDS
A4: 6060925957633 | B4: 603 | C4: 2013 | D4: East Tamaki | E4: 配送订单 | F4: 2025-06-14 17:31:00 | G4: 9 | I4: TEMU-SIN_LMD_NZL | J4: C2103951401 | K4: 派送 | L4: 新到件 | M4: AucklandDS
A5: 6061525944958 | B5: 211 | C5: 1072 | D5: Panmure | E5: 配送订单 | F5: 2025-06-19 17:06:30 | G5: 4 | I5: TEMU-SIN_LMD_NZL | J5: C2103951401 | K5: 派送 | L5: 盲派 | M5: AucklandDS
A6: 6061625964921 | B6: 211 | C6: 1072 | D6: Panmure | E6: 配送订单 | F6: 2025-06-19 17:28:47 | G6: 4 | I6: TEMU-SIN_LMD_NZL | J6: C2103951401 | K6: 派送 | L6: 盲派 | M6: AucklandDS
A7: 6061625947049 | B7: 203 B | C7: 1041 | D7: Mount Roskill | E7: 配送订单 | F7: 2025-06-21 13:57:24 | G7: 3 | I7: TEMU-SIN_LMD_NZL | J7: C2103951401 | K7: 派送 | L7: 盲派 | M7: AucklandDS
A8: 6061725998901 | B8: 405 C | C8: 0612 | D8: Henderson | E8: 配送订单 | F8: 2025-06-21 18:09:06 | G8: 2 | I8: TEMU-SIN_LMD_NZL | J8: C2103951401 | K8: 派送 | L8: 盲派 | M8: AucklandDS
A9: 6061825992297 | B9: 405 C | C9: 0612 | D9: Henderson | E9: 配送订单 | F9: 2025-06-23 12:35:27 | G9: 1 | I9: TEMU-SIN_LMD_NZL | J9: C2103951401 | K9: 派送 | L9: 新到件 | M9: AucklandDS
A10: 6061825922308 | B10: 209 | C10: 1062 | D10: Otahuhu | E10: 配送订单 | F10: 2025-06-23 14:00:54 | G10: 1 | I10: TEMU-SIN_LMD_NZL | J10: C2103951401 | K10: 派送 | L10: 新到件 | M10: AucklandDS
A11: 3661049903796 | B11: 310 | C11: 0931 | D11: Orewa | E11: 配送订单 | F11: 2025-06-23 15:32:02 | G11: 1 | I11: AliExpress_NZL_Cainiao | J11: C2103960401 | K11: 派送 | L11: 新到件 | M11: AucklandDS
A12: 6061925973413 | B12: 307 B | C12: 0630 | D12: Murrays Bay | E12: 配送订单 | F12: 2025-06-23 16:24:24 | G12: 0 | I12: TEMU-SIN_LMD_NZL | J12: C2103951401 | K12: 派送 | L12: 新到件 | M12: AucklandDS
A13: 3661049899435 | B13: 107 | C13: 1023 | D13: Auckland | E13: 配送订单 | F13: 2025-06-23 16:52:30 | G13: 0 | I13: AliExpress_NZL_Cainiao | J13: C2103960401 | K13: 派送 | L13: 新到件 | M13: AucklandDS
... A7135: 6061525964457 | B7135: 406 | C7135: 0614 | D7135: Massey | E7135: 配送订单 | F7135: 2025-06-23 16:48:57 | G7135: 0 | I7135: TEMU-SIN_LMD_NZL | J7135: C2103951401 | K7135: 派送 | L7135: 预约派件 | M7135: AucklandDS
